<?xml version="1.0" encoding="utf-8"?>
<!-- =================================================================================== -->
<!-- |    This document was autogenerated by xacro from lula_franka.urdf.xacro         | -->
<!-- |    EDITING THIS FILE BY HAND IS NOT RECOMMENDED                                 | -->
<!-- =================================================================================== -->
<!-- This file has been modified from the one in "omni.isaac.motion_generation" to have
     and end-effector frame that matches the official URDF of Franka arm. -->
<robot name="franka_inspire_combined" xmlns:xacro="http://www.ros.org/wiki/xacro">
  <material name="aluminum">
    <color rgba="0.5 0.5 0.5 1"/>
  </material>
  <!-- camera body, with origin at bottom screw mount -->
  <joint name="camera_joint" type="fixed">
    <origin rpy="0 -1.57079632679 3.14159265359" xyz="0.0358116 0 0.0360562"/>
    <parent link="panda_hand"/>
    <child link="camera_bottom_screw_frame"/>
  </joint>
  <link name="camera_bottom_screw_frame"/>
  <joint name="camera_link_joint" type="fixed">
    <origin rpy="0 0 0" xyz="0 0.02 0.0115"/>
    <parent link="camera_bottom_screw_frame"/>
    <child link="camera_link"/>
  </joint>
  <link name="camera_link">
    <visual>
      <origin rpy="1.57079632679 0 1.57079632679" xyz="0.00987 -0.02 0"/>
      <geometry>
        <box size="0.099 0.023 0.02005"/>
        <!--<mesh filename="package://realsense2_camera/meshes/d415.stl" />-->
      </geometry>
      <material name="aluminum"/>
    </visual>
    <collision>
      <origin rpy="0 0 0" xyz="0 -0.02 0"/>
      <geometry>
        <box size="0.02005 0.099 0.023"/>
      </geometry>
    </collision>
    <inertial>
      <!-- The following are not reliable values, and should not be used for modeling -->
      <mass value="0.564"/>
      <origin xyz="0 0 0"/>
      <inertia ixx="0.003881243" ixy="0.0" ixz="0.0" iyy="0.000498940" iyz="0.0" izz="0.003879257"/>
    </inertial>
  </link>
  <!-- camera depth joints and links -->
  <joint name="camera_depth_joint" type="fixed">
    <origin rpy="0 0 0" xyz="0 0 0"/>
    <parent link="camera_link"/>
    <child link="camera_depth_frame"/>
  </joint>
  <link name="camera_depth_frame"/>
  <joint name="camera_depth_optical_joint" type="fixed">
    <origin rpy="-1.57079632679 0 -1.57079632679" xyz="0 0 0"/>
    <parent link="camera_depth_frame"/>
    <child link="camera_depth_optical_frame"/>
  </joint>
  <link name="camera_depth_optical_frame"/>
  <!-- camera left IR joints and links -->
  <joint name="camera_left_ir_joint" type="fixed">
    <origin rpy="0 0 0" xyz="0 0.0 0"/>
    <parent link="camera_depth_frame"/>
    <child link="camera_left_ir_frame"/>
  </joint>
  <link name="camera_left_ir_frame"/>
  <joint name="camera_left_ir_optical_joint" type="fixed">
    <origin rpy="-1.57079632679 0 -1.57079632679" xyz="0 0 0"/>
    <parent link="camera_left_ir_frame"/>
    <child link="camera_left_ir_optical_frame"/>
  </joint>
  <link name="camera_left_ir_optical_frame"/>
  <!-- camera right IR joints and links -->
  <joint name="camera_right_ir_joint" type="fixed">
    <origin rpy="0 0 0" xyz="0 -0.055 0"/>
    <parent link="camera_depth_frame"/>
    <child link="camera_right_ir_frame"/>
  </joint>
  <link name="camera_right_ir_frame"/>
  <joint name="camera_right_ir_optical_joint" type="fixed">
    <origin rpy="-1.57079632679 0 -1.57079632679" xyz="0 0 0"/>
    <parent link="camera_right_ir_frame"/>
    <child link="camera_right_ir_optical_frame"/>
  </joint>
  <link name="camera_right_ir_optical_frame"/>
  <!-- camera color joints and links -->
  <joint name="camera_color_joint" type="fixed">
    <origin rpy="0 0 0" xyz="0 0.015 0"/>
    <parent link="camera_depth_frame"/>
    <child link="camera_color_frame"/>
  </joint>
  <link name="camera_color_frame"/>
  <joint name="camera_color_optical_joint" type="fixed">
    <origin rpy="-1.57079632679 0 -1.57079632679" xyz="0 0 0"/>
    <parent link="camera_color_frame"/>
    <child link="camera_color_optical_frame"/>
  </joint>
  <link name="camera_color_optical_frame"/>
  <link name="panda_link0">
    <visual>
      <geometry>
        <mesh filename="package://franka_description/meshes/visual/link0.dae"/>
      </geometry>
    </visual>
    <collision>
      <geometry>
        <mesh filename="package://franka_description/meshes/collision/link0.stl"/>
      </geometry>
    </collision>
  </link>
  <link name="panda_link1">
    <visual>
      <geometry>
        <mesh filename="package://franka_description/meshes/visual/link1.dae"/>
      </geometry>
    </visual>
    <collision>
      <geometry>
        <mesh filename="package://franka_description/meshes/collision/link1.stl"/>
      </geometry>
    </collision>
  </link>
  <joint name="panda_joint1" type="revolute">
    <safety_controller k_position="100.0" k_velocity="40.0" soft_lower_limit="-2.8973" soft_upper_limit="2.8973"/>
    <origin rpy="0 0 0" xyz="0 0 0.333"/>
    <parent link="panda_link0"/>
    <child link="panda_link1"/>
    <axis xyz="0 0 1"/>
    <limit effort="87" lower="-2.8973" upper="2.8973" velocity="2.1750"/>
  </joint>
  <link name="panda_link2">
    <visual>
      <geometry>
        <mesh filename="package://franka_description/meshes/visual/link2.dae"/>
      </geometry>
    </visual>
    <collision>
      <geometry>
        <mesh filename="package://franka_description/meshes/collision/link2.stl"/>
      </geometry>
    </collision>
  </link>
  <joint name="panda_joint2" type="revolute">
    <safety_controller k_position="100.0" k_velocity="40.0" soft_lower_limit="-1.7628" soft_upper_limit="1.7628"/>
    <origin rpy="-1.57079632679 0 0" xyz="0 0 0"/>
    <parent link="panda_link1"/>
    <child link="panda_link2"/>
    <axis xyz="0 0 1"/>
    <limit effort="87" lower="-1.7628" upper="1.7628" velocity="2.1750"/>
  </joint>
  <link name="panda_link3">
    <visual>
      <geometry>
        <mesh filename="package://franka_description/meshes/visual/link3.dae"/>
      </geometry>
    </visual>
    <collision>
      <geometry>
        <mesh filename="package://franka_description/meshes/collision/link3.stl"/>
      </geometry>
    </collision>
  </link>
  <joint name="panda_joint3" type="revolute">
    <safety_controller k_position="100.0" k_velocity="40.0" soft_lower_limit="-2.8973" soft_upper_limit="2.8973"/>
    <origin rpy="1.57079632679 0 0" xyz="0 -0.316 0"/>
    <parent link="panda_link2"/>
    <child link="panda_link3"/>
    <axis xyz="0 0 1"/>
    <limit effort="87" lower="-2.8973" upper="2.8973" velocity="2.1750"/>
  </joint>
  <link name="panda_link4">
    <visual>
      <geometry>
        <mesh filename="package://franka_description/meshes/visual/link4.dae"/>
      </geometry>
    </visual>
    <collision>
      <geometry>
        <mesh filename="package://franka_description/meshes/collision/link4.stl"/>
      </geometry>
    </collision>
  </link>
  <joint name="panda_joint4" type="revolute">
    <safety_controller k_position="100.0" k_velocity="40.0" soft_lower_limit="-3.0718" soft_upper_limit="-0.0698"/>
    <origin rpy="1.57079632679 0 0" xyz="0.0825 0 0"/>
    <parent link="panda_link3"/>
    <child link="panda_link4"/>
    <axis xyz="0 0 1"/>
    <limit effort="87" lower="-3.0718" upper="-0.0698" velocity="2.1750"/>
  </joint>
  <link name="panda_link5">
    <visual>
      <geometry>
        <mesh filename="package://franka_description/meshes/visual/link5.dae"/>
      </geometry>
    </visual>
    <collision>
      <geometry>
        <mesh filename="package://franka_description/meshes/collision/link5.stl"/>
      </geometry>
    </collision>
  </link>
  <joint name="panda_joint5" type="revolute">
    <safety_controller k_position="100.0" k_velocity="40.0" soft_lower_limit="-2.8973" soft_upper_limit="2.8973"/>
    <origin rpy="-1.57079632679 0 0" xyz="-0.0825 0.384 0"/>
    <parent link="panda_link4"/>
    <child link="panda_link5"/>
    <axis xyz="0 0 1"/>
    <limit effort="12" lower="-2.8973" upper="2.8973" velocity="2.6100"/>
  </joint>
  <link name="panda_link6">
    <visual>
      <geometry>
        <mesh filename="package://franka_description/meshes/visual/link6.dae"/>
      </geometry>
    </visual>
    <collision>
      <geometry>
        <mesh filename="package://franka_description/meshes/collision/link6.stl"/>
      </geometry>
    </collision>
  </link>
  <joint name="panda_joint6" type="revolute">
    <safety_controller k_position="100.0" k_velocity="40.0" soft_lower_limit="-0.0175" soft_upper_limit="3.7525"/>
    <origin rpy="1.57079632679 0 0" xyz="0 0 0"/>
    <parent link="panda_link5"/>
    <child link="panda_link6"/>
    <axis xyz="0 0 1"/>
    <limit effort="12" lower="-0.0175" upper="3.7525" velocity="2.6100"/>
  </joint>
  <link name="panda_link7">
    <visual>
      <geometry>
        <mesh filename="package://franka_description/meshes/visual/link7.dae"/>
      </geometry>
    </visual>
    <collision>
      <geometry>
        <mesh filename="package://franka_description/meshes/collision/link7.stl"/>
      </geometry>
    </collision>
  </link>
  <joint name="panda_joint7" type="revolute">
    <safety_controller k_position="100.0" k_velocity="40.0" soft_lower_limit="-2.8973" soft_upper_limit="2.8973"/>
    <origin rpy="1.57079632679 0 0" xyz="0.088 0 0"/>
    <parent link="panda_link6"/>
    <child link="panda_link7"/>
    <axis xyz="0 0 1"/>
    <limit effort="12" lower="-2.8973" upper="2.8973" velocity="2.6100"/>
  </joint>
  <link name="panda_link8"/>
  <joint name="panda_joint8" type="fixed">
    <origin rpy="0 0 0" xyz="0 0 0.107"/>
    <parent link="panda_link7"/>
    <child link="panda_link8"/>
    <axis xyz="0 0 0"/>
  </joint>
  <joint name="panda_hand_joint" type="fixed">
    <parent link="panda_link8"/>
    <child link="panda_hand"/>
    <origin rpy="0 0 -0.785398163397" xyz="0 0 0"/>
  </joint>
  <link name="panda_hand">
    <visual>
      <geometry>
        <mesh filename="package://franka_description/meshes/visual/hand.dae"/>
      </geometry>
    </visual>
    <collision>
      <geometry>
        <mesh filename="package://franka_description/meshes/collision/hand.stl"/>
      </geometry>
    </collision>
  </link>
  <link name="panda_leftfinger">
    <visual>
      <geometry>
        <mesh filename="package://franka_description/meshes/visual/finger.dae"/>
      </geometry>
    </visual>
    <collision>
      <geometry>
        <mesh filename="package://franka_description/meshes/collision/finger.stl"/>
      </geometry>
    </collision>
  </link>
  <link name="panda_rightfinger">
    <visual>
      <origin rpy="0 0 3.14159265359" xyz="0 0 0"/>
      <geometry>
        <mesh filename="package://franka_description/meshes/visual/finger.dae"/>
      </geometry>
    </visual>
    <collision>
      <origin rpy="0 0 3.14159265359" xyz="0 0 0"/>
      <geometry>
        <mesh filename="package://franka_description/meshes/collision/finger.stl"/>
      </geometry>
    </collision>
  </link>
  <joint name="panda_finger_joint1" type="prismatic">
    <parent link="panda_hand"/>
    <child link="panda_leftfinger"/>
    <origin rpy="0 0 0" xyz="0 0 0.0584"/>
    <axis xyz="0 1 0"/>
    <limit effort="20" lower="0.0" upper="0.04" velocity="0.2"/>
  </joint>
  <joint name="panda_finger_joint2" type="prismatic">
    <parent link="panda_hand"/>
    <child link="panda_rightfinger"/>
    <origin rpy="0 0 0" xyz="0 0 0.0584"/>
    <axis xyz="0 -1 0"/>
    <limit effort="20" lower="0.0" upper="0.04" velocity="0.2"/>
    <mimic joint="panda_finger_joint1"/>
  </joint>
  <link name="base_link"/>
  <joint name="base_link_robot" type="fixed">
    <origin rpy="0 0 0" xyz="0.0 0.0 0.0"/>
    <axis xyz="0 0 1"/>
    <parent link="base_link"/>
    <child link="panda_link0"/>
  </joint>
  <link name="right_gripper"/>
  <joint name="right_gripper" type="fixed">
    <origin rpy="0 0 2.35619449019" xyz="0.0 0 0.1"/>
    <axis xyz="0 0 1"/>
    <parent link="panda_link8"/>
    <child link="right_gripper"/>
  </joint>
  <link name="panda_rightfingertip"/>
  <joint name="panda_rightfingertip" type="fixed">
    <origin rpy="0 0 3.14159265359" xyz="0.0 0 0.045"/>
    <axis xyz="0 0 1"/>
    <parent link="panda_rightfinger"/>
    <child link="panda_rightfingertip"/>
  </joint>
  <link name="panda_leftfingertip"/>
  <joint name="panda_leftfingertip" type="fixed">
    <origin rpy="0 0 3.14159265359" xyz="0.0 0 0.045"/>
    <axis xyz="0 0 1"/>
    <parent link="panda_leftfinger"/>
    <child link="panda_leftfingertip"/>
  </joint>
  <link name="panda_forearm_end_pt"/>
  <joint name="panda_forearm_end_pt" type="fixed">
    <origin rpy="0 0 0.0" xyz="-0.09 0.02 0.0"/>
    <axis xyz="0 0 1"/>
    <parent link="panda_link4"/>
    <child link="panda_forearm_end_pt"/>
  </joint>
  <link name="panda_forearm_mid_pt"/>
  <joint name="panda_forearm_mid_pt" type="fixed">
    <origin rpy="0 0 0" xyz="0.0 0.175 0.0"/>
    <axis xyz="0 0 1"/>
    <parent link="panda_forearm_end_pt"/>
    <child link="panda_forearm_mid_pt"/>
  </joint>
  <link name="panda_forearm_mid_pt_shifted"/>
  <joint name="panda_forearm_mid_pt_shifted" type="fixed">
    <origin rpy="0 0 0" xyz="0.0 0.0 -0.05"/>
    <axis xyz="0 0 1"/>
    <parent link="panda_forearm_mid_pt"/>
    <child link="panda_forearm_mid_pt_shifted"/>
  </joint>
  <link name="panda_forearm_distal"/>
  <joint name="panda_forearm_distal" type="fixed">
    <origin rpy="0 0 0" xyz="0.0 0.1 0.0"/>
    <axis xyz="0 0 1"/>
    <parent link="panda_link5"/>
    <child link="panda_forearm_distal"/>
  </joint>
  <link name="panda_wrist_end_pt"/>
  <joint name="panda_wrist_end_pt" type="fixed">
    <origin rpy="0 0 0.0" xyz="0.0 0.0 -0.07"/>
    <axis xyz="0 0 1"/>
    <parent link="panda_link7"/>
    <child link="panda_wrist_end_pt"/>
  </joint>
  <link name="panda_face_left"/>
  <joint name="panda_face_left" type="fixed">
    <origin rpy="0 0 0" xyz="0.0 0.07 0.04"/>
    <axis xyz="0 0 1"/>
    <parent link="panda_hand"/>
    <child link="panda_face_left"/>
  </joint>
  <link name="panda_face_right"/>
  <joint name="panda_face_right" type="fixed">
    <origin rpy="0 0 0" xyz="0.0 -0.07 0.04"/>
    <axis xyz="0 0 1"/>
    <parent link="panda_hand"/>
    <child link="panda_face_right"/>
  </joint>
  <link name="panda_face_back_left"/>
  <joint name="panda_face_back_left" type="fixed">
    <origin rpy="0 0 0" xyz="0.0 0.07 0.0"/>
    <axis xyz="0 0 1"/>
    <parent link="panda_hand"/>
    <child link="panda_face_back_left"/>
  </joint>
  <link name="panda_face_back_right"/>
  <joint name="panda_face_back_right" type="fixed">
    <origin rpy="0 0 0" xyz="0.0 -0.07 0.0"/>
    <axis xyz="0 0 1"/>
    <parent link="panda_hand"/>
    <child link="panda_face_back_right"/>
  </joint>

  <!-- Modifications made to the one from Lula library -->
  <link name="panda_end_effector"/>
  <joint name="panda_end_effector" type="fixed">
    <origin rpy="0 0 0" xyz="0 0 0.107"/>
    <parent link="panda_hand"/>
    <child link="panda_end_effector"/>
  </joint>


  <!-- Connection joint: Franka end effector to Inspire Hand -->
  <joint name="franka_to_inspire_hand" type="fixed">
    <origin rpy="0 0 0" xyz="0 0 0"/>
    <parent link="panda_end_effector"/>
    <child link="base_link"/>
  </joint>

<link name="base_link">
    <inertial>
      <origin
        xyz="2e-05 -0.0024500000000000004 0.07793000000000001"
        rpy="0 0 0" />
      <mass
        value="0.6273500000000001" />
      <inertia
        ixx="0.0014968368000000001"
        ixy="-1.64393e-06"
        ixz="2.527401e-05"
        iyy="0.0017872599099999999"
        iyz="0.00012212543"
        izz="0.00071434062" />
    </inertial>
    <visual>
      <origin
        xyz="0 0 0"
        rpy="0 0 0" />
      <geometry>
        <mesh
          filename="../meshes/base_link.STL" />
      </geometry>
      <material name="">
        <color rgba="1 1 1 1" />
      </material>
    </visual>
    <collision>
      <origin
        xyz="0 0 0"
        rpy="0 0 0" />
      <geometry>
        <mesh
          filename="../meshes/base_link.STL" />
      </geometry>
    </collision>
  </link>

  <link
    name="palm_force_sensor">
    <inertial>
      <origin
        xyz="0.000120426871221421 0.000717269582936034 -0.0006928935004962"
        rpy="0 0 0" />
      <mass
        value="0.001" />
      <inertia
        ixx="1.792409847502E-07"
        ixy="3.5297874278755E-10"
        ixz="-2.06007907879908E-10"
        iyy="5.01925280756008E-07"
        iyz="-4.23310809567535E-10"
        izz="6.80058307355101E-07" />
    </inertial>
    <visual>
      <origin
        xyz="0 0 0"
        rpy="0 0 0" />
      <geometry>
        <mesh
          filename="../meshes/palm_force_sensor.STL" />
      </geometry>
      <material
        name="">
        <color
          rgba="0.411764705882353 0.411764705882353 0.411764705882353 1" />
      </material>
    </visual>
    <collision>
      <origin
        xyz="0 0 0"
        rpy="0 0 0" />
      <geometry>
        <mesh
          filename="../meshes/palm_force_sensor.STL" />
      </geometry>
    </collision>
  </link>
  <joint
    name="palm_force_sensor_joint"
    type="fixed">
    <origin
      xyz="-0.00036819 0.012296 0.1196"
      rpy="1.5708 0 -3.1416" />
    <parent
      link="base_link" />
    <child
      link="palm_force_sensor" />
    <axis
      xyz="0 0 0" />
  </joint>
  <link
    name="right_thumb_1">
    <inertial>
      <origin
        xyz="-0.026949999999999998 0.01478 0.07485"
        rpy="0 0 0" />
      <mass
        value="0.02407" />
      <inertia
        ixx="3.0396799999999998e-06"
        ixy="1.2416e-07"
        ixz="-8.392e-08"
        iyy="1.62329e-06"
        iyz="6.3491e-07"
        izz="2.25191e-06" />
    </inertial>
    <visual>
      <origin
        xyz="0 0 0"
        rpy="0 0 0" />
      <geometry>
        <mesh
          filename="../meshes/right_thumb_1.STL" />
      </geometry>
      <material
        name="">
        <color
          rgba="1 1 1 1" />
      </material>
    </visual>
    <collision>
      <origin
        xyz="0 0 0"
        rpy="0 0 0" />
      <geometry>
        <mesh
          filename="../meshes/right_thumb_1.STL" />
      </geometry>
    </collision>
  </link>
  <joint
    name="right_thumb_1_joint"
    type="revolute">
    <origin
      xyz="-0.0269 0.02101 0.0689"
      rpy="0 0 0" />
    <parent
      link="base_link" />
    <child
      link="right_thumb_1" />
    <axis
      xyz="0 0 -1" />
    <limit
      lower="0"
      upper="1.1641"
      effort="10"
      velocity="1" />
  </joint>
  <link
    name="right_thumb_2">
    <inertial>
      <origin
        xyz="-0.046509999999999996 0.0245 0.08531"
        rpy="0 0 0" />
      <mass
        value="0.02426" />
      <inertia
        ixx="3.80486e-06"
        ixy="7.243600000000001e-07"
        ixz="1.19724e-06"
        iyy="6.95218e-06"
        iyz="-4.1933e-07"
        izz="5.52002e-06" />
    </inertial>
    <visual>
      <origin
        xyz="0 0 0"
        rpy="0 0 0" />
      <geometry>
        <mesh
          filename="../meshes/right_thumb_2.STL" />
      </geometry>
      <material
        name="">
        <color
          rgba="1 1 1 1" />
      </material>
    </visual>
    <collision>
      <origin
        xyz="0 0 0"
        rpy="0 0 0" />
      <geometry>
        <mesh
          filename="../meshes/right_thumb_2.STL" />
      </geometry>
    </collision>
  </link>
  <joint
    name="right_thumb_2_joint"
    type="revolute">
    <origin
      xyz="-0.0079252 0.0090599 0.0052"
      rpy="1.5708 0 2.8798" />
    <parent
      link="right_thumb_1" />
    <child
      link="right_thumb_2" />
    <axis
      xyz="0 0 1" />
    <limit
      lower="0"
      upper="0.5864"
      effort="10"
      velocity="1" />
  </joint>
  <link
    name="right_thumb_3">
    <inertial>
      <origin
        xyz="-0.07454999999999999 0.03374 0.09742"
        rpy="0 0 0" />
      <mass
        value="0.01122" />
      <inertia
        ixx="1.11059e-06"
        ixy="1.5098e-07"
        ixz="3.9131000000000003e-07"
        iyy="1.5849400000000001e-06"
        iyz="-1.1285e-07"
        izz="1.18109e-06" />
    </inertial>
    <visual>
      <origin
        xyz="0 0 0"
        rpy="0 0 0" />
      <geometry>
        <mesh
          filename="../meshes/right_thumb_3.STL" />
      </geometry>
      <material
        name="">
        <color
          rgba="1 1 1 1" />
      </material>
    </visual>
    <collision>
      <origin
        xyz="0 0 0"
        rpy="0 0 0" />
      <geometry>
        <mesh
          filename="../meshes/right_thumb_3.STL" />
      </geometry>
    </collision>
  </link>
  <joint
    name="right_thumb_3_joint"
    type="revolute">
    <origin
      xyz="0.031403 0.021069 0.00095"
      rpy="0 0 0" />
    <parent
      link="right_thumb_2" />
    <child
      link="right_thumb_3" />
    <axis
      xyz="0 0 1" />
    <limit
      lower="0"
      upper="0.5"
      effort="10"
      velocity="1" />
    <mimic
        joint="right_thumb_2_joint"
        multiplier="0.8024"
        offset="0" />
  </joint>
  <link
    name="thumb_force_sensor_2">
    <inertial>
      <origin
        xyz="2.43300294987259E-05 5.45016031029619E-05 -0.00109137669633625"
        rpy="0 0 0" />
      <mass
        value="0.001" />
      <inertia
        ixx="3.34747183285769E-10"
        ixy="-3.83618671521233E-14"
        ixz="-3.52155403886961E-13"
        iyy="3.3582079154486E-10"
        iyz="1.08928107999936E-12"
        izz="5.8857712310973E-10" />
    </inertial>
    <visual>
      <origin
        xyz="0 0 0"
        rpy="0 0 0" />
      <geometry>
        <mesh
          filename="../meshes/thumb_force_sensor_2.STL" />
      </geometry>
      <material
        name="">
        <color
          rgba="0.411764705882353 0.411764705882353 0.411764705882353 1" />
      </material>
    </visual>
    <collision>
      <origin
        xyz="0 0 0"
        rpy="0 0 0" />
      <geometry>
        <mesh
          filename="../meshes/thumb_force_sensor_2.STL" />
      </geometry>
    </collision>
  </link>
  <joint
    name="thumb_force_sensor_2_joint"
    type="fixed">
    <origin
      xyz="0.011771 0.01699 -0.0077514"
      rpy="1.8405 -1.5705 3.1416" />
    <parent
      link="right_thumb_3" />
    <child
      link="thumb_force_sensor_2" />
    <axis
      xyz="0 0 0" />
  </joint>
  <link
    name="right_thumb_4">
    <inertial>
      <origin
        xyz="-0.1022 0.04117 0.1138"
        rpy="0 0 0" />
      <mass
        value="0.0189" />
      <inertia
        ixx="1.32723e-06"
        ixy="2.7513e-07"
        ixz="6.8709e-07"
        iyy="2.26117e-06"
        iyz="-1.8584999999999999e-07"
        izz="2.02611e-06" />
    </inertial>
    <visual>
      <origin
        xyz="0 0 0"
        rpy="0 0 0" />
      <geometry>
        <mesh
          filename="../meshes/right_thumb_4.STL" />
      </geometry>
      <material
        name="">
        <color
          rgba="1 1 1 1" />
      </material>
    </visual>
    <collision>
      <origin
        xyz="0 0 0"
        rpy="0 0 0" />
      <geometry>
        <mesh
          filename="../meshes/right_thumb_4.STL" />
      </geometry>
    </collision>
  </link>
  <joint
    name="right_thumb_4_joint"
    type="revolute">
    <origin
      xyz="0.021903 0.012816 -0.0003"
      rpy="0 0 0" />
    <parent
      link="right_thumb_3" />
    <child
      link="right_thumb_4" />
    <axis
      xyz="0 0 1" />
    <limit
      lower="0"
      upper="3.14"
      effort="10"
      velocity="1" />
    <mimic
        joint="right_thumb_3_joint"
        multiplier="0.9487"
        offset="0" />
  </joint>
  <link
    name="thumb_force_sensor_3">
    <inertial>
      <origin
        xyz="-1.23775059738263E-05 -0.000195169652742258 -0.000791740559016839"
        rpy="0 0 0" />
      <mass
        value="0.001" />
      <inertia
        ixx="5.41310691342173E-09"
        ixy="6.87296172207439E-13"
        ixz="6.30644149217552E-13"
        iyy="2.55911790350329E-09"
        iyz="3.82480948255569E-11"
        izz="7.82908815507693E-09" />
    </inertial>
    <visual>
      <origin
        xyz="0 0 0"
        rpy="0 0 0" />
      <geometry>
        <mesh
          filename="../meshes/thumb_force_sensor_3.STL" />
      </geometry>
      <material
        name="">
        <color
          rgba="0.411764705882353 0.411764705882353 0.411764705882353 1" />
      </material>
    </visual>
    <collision>
      <origin
        xyz="0 0 0"
        rpy="0 0 0" />
      <geometry>
        <mesh
          filename="../meshes/thumb_force_sensor_3.STL" />
      </geometry>
    </collision>
  </link>
  <joint
    name="thumb_force_sensor_3_joint"
    type="fixed">
    <origin
      xyz="0.014598 0.01472 -0.0073103"
      rpy="-0.20892 -1.5708 -0.81953" />
    <parent
      link="right_thumb_4" />
    <child
      link="thumb_force_sensor_3" />
    <axis
      xyz="0 0 0" />
  </joint>
  <link
    name="thumb_force_sensor_4">
    <inertial>
      <origin
        xyz="-7.92360954363081E-07 0.000270176676441192 -0.00100449430451509"
        rpy="0 0 0" />
      <mass
        value="0.001" />
      <inertia
        ixx="8.13571079919818E-11"
        ixy="2.58693510294188E-14"
        ixz="-1.96984280101514E-14"
        iyy="1.7077491736553E-10"
        iyz="-3.77214180289288E-12"
        izz="2.11640709143909E-10" />
    </inertial>
    <visual>
      <origin
        xyz="0 0 0"
        rpy="0 0 0" />
      <geometry>
        <mesh
          filename="../meshes/thumb_force_sensor_4.STL" />
      </geometry>
      <material
        name="">
        <color
          rgba="0.411764705882353 0.411764705882353 0.411764705882353 1" />
      </material>
    </visual>
    <collision>
      <origin
        xyz="0 0 0"
        rpy="0 0 0" />
      <geometry>
        <mesh
          filename="../meshes/thumb_force_sensor_4.STL" />
      </geometry>
    </collision>
  </link>
  <joint
    name="thumb_force_sensor_4_joint"
    type="fixed">
    <origin
      xyz="0.028987 0.017301 -0.0073512"
      rpy="1.6795 1.5708 2.7448" />
    <parent
      link="right_thumb_4" />
    <child
      link="thumb_force_sensor_4" />
    <axis
      xyz="0 0 0" />
  </joint>
  <link
    name="thumb_force_sensor_1">
    <inertial>
      <origin
        xyz="1.67085981274823E-05 1.15915239991271E-05 -0.00107125254163185"
        rpy="0 0 0" />
      <mass
        value="0.001" />
      <inertia
        ixx="9.01126285102489E-09"
        ixy="-2.19183765993572E-15"
        ixz="-2.32024611820209E-12"
        iyy="4.94554439784859E-09"
        iyz="1.17775921788887E-11"
        izz="1.35651458253969E-08" />
    </inertial>
    <visual>
      <origin
        xyz="0 0 0"
        rpy="0 0 0" />
      <geometry>
        <mesh
          filename="../meshes/thumb_force_sensor_1.STL" />
      </geometry>
      <material
        name="">
        <color
          rgba="0.411764705882353 0.411764705882353 0.411764705882353 1" />
      </material>
    </visual>
    <collision>
      <origin
        xyz="0 0 0"
        rpy="0 0 0" />
      <geometry>
        <mesh
          filename="../meshes/thumb_force_sensor_1.STL" />
      </geometry>
    </collision>
  </link>
  <joint
    name="thumb_force_sensor_1_joint"
    type="fixed">
    <origin
      xyz="0.0087121 0.026305 -0.0067115"
      rpy="-1.5728 -1.5708 0.35156" />
    <parent
      link="right_thumb_2" />
    <child
      link="thumb_force_sensor_1" />
    <axis
      xyz="0 0 0" />
  </joint>
  <link
    name="right_index_1">
    <inertial>
      <origin
        xyz="-0.032229999999999995 0.0012 0.16325"
        rpy="0 0 0" />
      <mass
        value="0.02456" />
      <inertia
        ixx="6.214600000000001e-06"
        ixy="9.95e-09"
        ixz="1.6013e-07"
        iyy="6.14166e-06"
        iyz="-2.5293000000000003e-07"
        izz="1.37478e-06" />
    </inertial>
    <visual>
      <origin
        xyz="0 0 0"
        rpy="0 0 0" />
      <geometry>
        <mesh
          filename="../meshes/right_index_1.STL" />
      </geometry>
      <material
        name="">
        <color
          rgba="1 1 1 1" />
      </material>
    </visual>
    <collision>
      <origin
        xyz="0 0 0"
        rpy="0 0 0" />
      <geometry>
        <mesh
          filename="../meshes/right_index_1.STL" />
      </geometry>
    </collision>
  </link>
  <joint
    name="right_index_1_joint"
    type="revolute">
    <origin
      xyz="-0.038679 0.00056467 0.1564"
      rpy="1.6057 0 -1.5708" />
    <parent
      link="base_link" />
    <child
      link="right_index_1" />
    <axis
      xyz="0 0 1" />
    <limit
      lower="0"
      upper="1.4381"
      effort="10"
      velocity="1" />
  </joint>
  <link
    name="right_index_2">
    <inertial>
      <origin
        xyz="-0.03349 0.024120000000000003 0.19052000000000002"
        rpy="0 0 0" />
      <mass
        value="0.0124" />
      <inertia
        ixx="4.5689199999999996e-05"
        ixy="-4.3484e-07"
        ixz="4.3806e-07"
        iyy="2.01044e-05"
        iyz="2.1144599999999997e-05"
        izz="2.587996e-05" />
    </inertial>
    <visual>
      <origin
        xyz="0 0 0"
        rpy="0 0 0" />
      <geometry>
        <mesh
          filename="../meshes/right_index_2.STL" />
      </geometry>
      <material
        name="">
        <color
          rgba="1 1 1 1" />
      </material>
    </visual>
    <collision>
      <origin
        xyz="0 0 0"
        rpy="0 0 0" />
      <geometry>
        <mesh
          filename="../meshes/right_index_2.STL" />
      </geometry>
    </collision>
  </link>
  <joint
    name="right_index_2_joint"
    type="revolute">
    <origin
      xyz="-0.0034259 0.032596 -0.00055"
      rpy="0 0 0" />
    <parent
      link="right_index_1" />
    <child
      link="right_index_2" />
    <axis
      xyz="0 0 1" />
    <limit
      lower="0"
      upper="3.14"
      effort="10"
      velocity="1" />
    <mimic
        joint="right_index_1_joint"
        multiplier="1.0843"
        offset="0" />      
  </joint>
  <link
    name="index_force_sensor_2">
    <inertial>
      <origin
        xyz="3.91105790090857E-06 0.000206428506730846 -0.000722888656592813"
        rpy="0 0 0" />
      <mass
        value="0.001" />
      <inertia
        ixx="4.79878645065383E-09"
        ixy="-8.64076408119868E-11"
        ixz="-1.50330115198978E-12"
        iyy="2.43958893457374E-09"
        iyz="-3.05132448820234E-11"
        izz="7.12570334555721E-09" />
    </inertial>
    <visual>
      <origin
        xyz="0 0 0"
        rpy="0 0 0" />
      <geometry>
        <mesh
          filename="../meshes/index_force_sensor_2.STL" />
      </geometry>
      <material
        name="">
        <color
          rgba="0.411764705882353 0.411764705882353 0.411764705882353 1" />
      </material>
    </visual>
    <collision>
      <origin
        xyz="0 0 0"
        rpy="0 0 0" />
      <geometry>
        <mesh
          filename="../meshes/index_force_sensor_2.STL" />
      </geometry>
    </collision>
  </link>
  <joint
    name="index_force_sensor_2_joint"
    type="fixed">
    <origin
      xyz="-0.0081655 0.037446 -0.0060795"
      rpy="-1.5708 -1.5337 1.9196" />
    <parent
      link="right_index_2" />
    <child
      link="index_force_sensor_2" />
    <axis
      xyz="0 0 0" />
  </joint>
  <link
    name="index_force_sensor_3">
    <inertial>
      <origin
        xyz="-2.48722057788475E-05 -0.000345285689256153 -0.00133800038179009"
        rpy="0 0 0" />
      <mass
        value="0.001" />
      <inertia
        ixx="1.31974821284448E-10"
        ixy="5.65060068039544E-12"
        ixz="7.79117122469869E-13"
        iyy="2.53430134807533E-10"
        iyz="9.12198063131294E-12"
        izz="2.8053351791299E-10" />
    </inertial>
    <visual>
      <origin
        xyz="0 0 0"
        rpy="0 0 0" />
      <geometry>
        <mesh
          filename="../meshes/index_force_sensor_3.STL" />
      </geometry>
      <material
        name="">
        <color
          rgba="0.411764705882353 0.411764705882353 0.411764705882353 1" />
      </material>
    </visual>
    <collision>
      <origin
        xyz="0 0 0"
        rpy="0 0 0" />
      <geometry>
        <mesh
          filename="../meshes/index_force_sensor_3.STL" />
      </geometry>
    </collision>
  </link>
  <joint
    name="index_force_sensor_3_joint"
    type="fixed">
    <origin
      xyz="-0.0086237 0.052572 -0.0060954"
      rpy="-1.5708 -1.5252 0.87237" />
    <parent
      link="right_index_2" />
    <child
      link="index_force_sensor_3" />
    <axis
      xyz="0 0 0" />
  </joint>
  <link
    name="index_force_sensor_1">
    <inertial>
      <origin
        xyz="4.50639917342482E-06 0.000116571661332499 -0.000567443126962358"
        rpy="0 0 0" />
      <mass
        value="0.001" />
      <inertia
        ixx="3.38028798502951E-09"
        ixy="-5.04640338896759E-11"
        ixz="-2.15701714440087E-13"
        iyy="1.96412698995832E-09"
        iyz="-5.48195334354584E-12"
        izz="5.28079732652296E-09" />
    </inertial>
    <visual>
      <origin
        xyz="0 0 0"
        rpy="0 0 0" />
      <geometry>
        <mesh
          filename="../meshes/index_force_sensor_1.STL" />
      </geometry>
      <material
        name="">
        <color
          rgba="0.411764705882353 0.411764705882353 0.411764705882353 1" />
      </material>
    </visual>
    <collision>
      <origin
        xyz="0 0 0"
        rpy="0 0 0" />
      <geometry>
        <mesh
          filename="../meshes/index_force_sensor_1.STL" />
      </geometry>
    </collision>
  </link>
  <joint
    name="index_force_sensor_1_joint"
    type="fixed">
    <origin
      xyz="-0.012046 0.019649 -0.006651"
      rpy="-1.5708 -1.5351 1.3587" />
    <parent
      link="right_index_1" />
    <child
      link="index_force_sensor_1" />
    <axis
      xyz="0 0 0" />
  </joint>
  <link
    name="right_middle_1">
    <inertial>
      <origin
        xyz="-0.00983 -0.01618 0.16336"
        rpy="0 0 0" />
      <mass
        value="0.02456" />
      <inertia
        ixx="6.2201e-06"
        ixy="3.08e-09"
        ixz="-6.238000000000001e-08"
        iyy="6.08085e-06"
        iyz="5.9592e-07"
        izz="1.43272e-06" />
    </inertial>
    <visual>
      <origin
        xyz="0 0 0"
        rpy="0 0 0" />
      <geometry>
        <mesh
          filename="../meshes/right_middle_1.STL" />
      </geometry>
      <material
        name="">
        <color
          rgba="1 1 1 1" />
      </material>
    </visual>
    <collision>
      <origin
        xyz="0 0 0"
        rpy="0 0 0" />
      <geometry>
        <mesh
          filename="../meshes/right_middle_1.STL" />
      </geometry>
    </collision>
  </link>
  <joint
    name="right_middle_1_joint"
    type="revolute">
    <origin
      xyz="-0.0171 0.00056467 0.157"
      rpy="1.5708 0 -1.5708" />
    <parent
      link="base_link" />
    <child
      link="right_middle_1" />
    <axis
      xyz="0 0 1" />
    <limit
      lower="0"
      upper="1.4381"
      effort="10"
      velocity="1" />
  </joint>
  <link
    name="right_middle_2">
    <inertial>
      <origin
        xyz="-0.00928 -0.02389 0.21371"
        rpy="0 0 0" />
      <mass
        value="0.01299" />
      <inertia
        ixx="3.56712e-06"
        ixy="7.719999999999999e-09"
        ixz="-7.653e-08"
        iyy="3.63641e-06"
        iyz="3.398e-08"
        izz="3.7324e-07" />
    </inertial>
    <visual>
      <origin
        xyz="0 0 0"
        rpy="0 0 0" />
      <geometry>
        <mesh
          filename="../meshes/right_middle_2.STL" />
      </geometry>
      <material
        name="">
        <color
          rgba="1 1 1 1" />
      </material>
    </visual>
    <collision>
      <origin
        xyz="0 0 0"
        rpy="0 0 0" />
      <geometry>
        <mesh
          filename="../meshes/right_middle_2.STL" />
      </geometry>
    </collision>
  </link>
  <joint
    name="right_middle_2_joint"
    type="revolute">
    <origin
      xyz="-0.0034259 0.032596 -0.00055"
      rpy="0 0 0" />
    <parent
      link="right_middle_1" />
    <child
      link="right_middle_2" />
    <axis
      xyz="0 0 1" />
    <limit
      lower="0"
      upper="3.14"
      effort="10"
      velocity="1" />
    <mimic
        joint="right_middle_1_joint"
        multiplier="1.0843"
        offset="0" />
  </joint>
  <link
    name="middle_force_sensor_2">
    <inertial>
      <origin
        xyz="-3.55652627983399E-07 2.88666331397097E-05 -0.000722235489778011"
        rpy="0 0 0" />
      <mass
        value="0.001" />
      <inertia
        ixx="5.0422606271269E-09"
        ixy="3.96627458520336E-13"
        ixz="-3.26041478715661E-14"
        iyy="2.56807850635636E-09"
        iyz="3.53736208701199E-12"
        izz="7.49563436241948E-09" />
    </inertial>
    <visual>
      <origin
        xyz="0 0 0"
        rpy="0 0 0" />
      <geometry>
        <mesh
          filename="../meshes/middle_force_sensor_2.STL" />
      </geometry>
      <material
        name="">
        <color
          rgba="0.411764705882353 0.411764705882353 0.411764705882353 1" />
      </material>
    </visual>
    <collision>
      <origin
        xyz="0 0 0"
        rpy="0 0 0" />
      <geometry>
        <mesh
          filename="../meshes/middle_force_sensor_2.STL" />
      </geometry>
    </collision>
  </link>
  <joint
    name="middle_force_sensor_2_joint"
    type="fixed">
    <origin
      xyz="-0.0090859 0.040963 -0.0061003"
      rpy="2.7687 -1.5708 3.885" />
    <parent
      link="right_middle_2" />
    <child
      link="middle_force_sensor_2" />
    <axis
      xyz="0 0 0" />
  </joint>
  <link
    name="middle_force_sensor_3">
    <inertial>
      <origin
        xyz="6.04731043574169E-08 -0.00036544534557964 -0.00127683945630336"
        rpy="0 0 0" />
      <mass
        value="0.001" />
      <inertia
        ixx="1.27227764572837E-10"
        ixy="1.00476590749141E-14"
        ixz="8.57880628295176E-15"
        iyy="2.43691164484046E-10"
        iyz="7.61272996067342E-12"
        izz="2.7587517056304E-10" />
    </inertial>
    <visual>
      <origin
        xyz="0 0 0"
        rpy="0 0 0" />
      <geometry>
        <mesh
          filename="../meshes/middle_force_sensor_3.STL" />
      </geometry>
      <material
        name="">
        <color
          rgba="0.411764705882353 0.411764705882353 0.411764705882353 1" />
      </material>
    </visual>
    <collision>
      <origin
        xyz="0 0 0"
        rpy="0 0 0" />
      <geometry>
        <mesh
          filename="../meshes/middle_force_sensor_3.STL" />
      </geometry>
    </collision>
  </link>
  <joint
    name="middle_force_sensor_3_joint"
    type="fixed">
    <origin
      xyz="-0.0098294 0.056051 -0.0061006"
      rpy="2.4672 -1.5708 3.14" />
    <parent
      link="right_middle_2" />
    <child
      link="middle_force_sensor_3" />
    <axis
      xyz="0 0 0" />
  </joint>
  <link
    name="middle_force_sensor_1">
    <inertial>
      <origin
        xyz="3.42843697213185E-07 0.000116657509605197 -0.000567442695803486"
        rpy="0 0 0" />
      <mass
        value="0.001" />
      <inertia
        ixx="3.38208410519618E-09"
        ixy="1.8756957436983E-13"
        ixz="-1.99647221364603E-14"
        iyy="1.96233204624223E-09"
        iyz="-5.48580562274466E-12"
        izz="5.2807983995112E-09" />
    </inertial>
    <visual>
      <origin
        xyz="0 0 0"
        rpy="0 0 0" />
      <geometry>
        <mesh
          filename="../meshes/middle_force_sensor_1.STL" />
      </geometry>
      <material
        name="">
        <color
          rgba="0.411764705882353 0.411764705882353 0.411764705882353 1" />
      </material>
    </visual>
    <collision>
      <origin
        xyz="0 0 0"
        rpy="0 0 0" />
      <geometry>
        <mesh
          filename="../meshes/middle_force_sensor_1.STL" />
      </geometry>
    </collision>
  </link>
  <joint
    name="middle_force_sensor_1_joint"
    type="fixed">
    <origin
      xyz="-0.012046 0.019649 -0.006651"
      rpy="2.9295 -1.5708 3.14" />
    <parent
      link="right_middle_1" />
    <child
      link="middle_force_sensor_1" />
    <axis
      xyz="0 0 0" />
  </joint>
  <link
    name="right_ring_1">
     <inertial>
      <origin
        xyz="0.011519999999999999 0.0010500000000000002 0.16331"
        rpy="0 0 0" />
      <mass
        value="0.02564" />
      <inertia
        ixx="6.281510000000001e-06"
        ixy="-1.501e-08"
        ixz="-2.6019e-07"
        iyy="6.20342e-06"
        iyz="-2.1600999999999999e-07"
        izz="1.4026700000000002e-06" />
    </inertial>
    <visual>
      <origin
        xyz="0 0 0"
        rpy="0 0 0" />
      <geometry>
        <mesh
          filename="../meshes/right_ring_1.STL" />
      </geometry>
      <material
        name="">
        <color
          rgba="1 1 1 1" />
      </material>
    </visual>
    <collision>
      <origin
        xyz="0 0 0"
        rpy="0 0 0" />
      <geometry>
        <mesh
          filename="../meshes/right_ring_1.STL" />
      </geometry>
    </collision>
  </link>
  <joint
    name="right_ring_1_joint"
    type="revolute">
    <origin
      xyz="0.0045302 0.00056467 0.15683"
      rpy="1.5184 0 -1.5708" />
    <parent
      link="base_link" />
    <child
      link="right_ring_1" />
    <axis
      xyz="0 0 1" />
    <limit
      lower="0"
      upper="1.4381"
      effort="10"
      velocity="1" />
  </joint>
  <link
    name="right_ring_2">
    <inertial>
      <origin
        xyz="0.01267 0.024120000000000003 0.19037"
        rpy="0 0 0" />
      <mass
        value="0.0124" />
      <inertia
        ixx="4.56148e-05"
        ixy="1.40969e-06"
        ixz="-1.28852e-06"
        iyy="2.01044e-05"
        iyz="2.110204e-05"
        izz="2.595436e-05" />
    </inertial>
    <visual>
      <origin
        xyz="0 0 0"
        rpy="0 0 0" />
      <geometry>
        <mesh
          filename="../meshes/right_ring_2.STL" />
      </geometry>
      <material
        name="">
        <color
          rgba="1 1 1 1" />
      </material>
    </visual>
    <collision>
      <origin
        xyz="0 0 0"
        rpy="0 0 0" />
      <geometry>
        <mesh
          filename="../meshes/right_ring_2.STL" />
      </geometry>
    </collision>
  </link>
  <joint
    name="right_ring_2_joint"
    type="revolute">
    <origin
      xyz="-0.0034259 0.032596 -0.00055"
      rpy="0 0 0" />
    <parent
      link="right_ring_1" />
    <child
      link="right_ring_2" />
    <axis
      xyz="0 0 1" />
    <limit
      lower="0"
      upper="3.14"
      effort="10"
      velocity="1" />
    <mimic
        joint="right_ring_1_joint"
        multiplier="1.0843"
        offset="0" />
  </joint>
  <link
    name="ring_force_sensor_2">
    <inertial>
      <origin
        xyz="-1.52436836100122E-05 0.000205901966578506 -0.000722888420897932"
        rpy="0 0 0" />
      <mass
        value="0.001" />
      <inertia
        ixx="4.79446001367797E-09"
        ixy="1.32867587230544E-10"
        ixz="1.3319969497832E-12"
        iyy="2.44391505492957E-09"
        iyz="-3.05212434039785E-11"
        izz="7.12570290551646E-09" />
    </inertial>
    <visual>
      <origin
        xyz="0 0 0"
        rpy="0 0 0" />
      <geometry>
        <mesh
          filename="../meshes/ring_force_sensor_2.STL" />
      </geometry>
      <material
        name="">
        <color
          rgba="0.411764705882353 0.411764705882353 0.411764705882353 1" />
      </material>
    </visual>
    <collision>
      <origin
        xyz="0 0 0"
        rpy="0 0 0" />
      <geometry>
        <mesh
          filename="../meshes/ring_force_sensor_2.STL" />
      </geometry>
    </collision>
  </link>
  <joint
    name="ring_force_sensor_2_joint"
    type="fixed">
    <origin
      xyz="-0.00816549212353353 0.0374457610846523 -0.00607949056508933"
      rpy="1.57079632679487 -1.51508890383765 -1.22202982373572" />
    <parent
      link="right_ring_2" />
    <child
      link="ring_force_sensor_2" />
    <axis
      xyz="0 0 0" />
  </joint>
  <link
    name="ring_force_sensor_3">
    <inertial>
      <origin
        xyz="1.45480090249107E-05 -0.000345868489067203 -0.00133799622683203"
        rpy="0 0 0" />
      <mass
        value="0.001" />
      <inertia
        ixx="1.32268380918037E-10"
        ixy="-8.21005557691383E-12"
        ixz="-2.63863504125309E-13"
        iyy="2.53139740379503E-10"
        iyz="9.1510626727994E-12"
        izz="2.80536239837899E-10" />
    </inertial>
    <visual>
      <origin
        xyz="0 0 0"
        rpy="0 0 0" />
      <geometry>
        <mesh
          filename="../meshes/ring_force_sensor_3.STL" />
      </geometry>
      <material
        name="">
        <color
          rgba="0.411764705882353 0.411764705882353 0.411764705882353 1" />
      </material>
    </visual>
    <collision>
      <origin
        xyz="0 0 0"
        rpy="0 0 0" />
      <geometry>
        <mesh
          filename="../meshes/ring_force_sensor_3.STL" />
      </geometry>
    </collision>
  </link>
  <joint
    name="ring_force_sensor_3_joint"
    type="fixed">
    <origin
      xyz="-0.00862372785817732 0.0525719273258207 -0.00609538761271226"
      rpy="1.57079632679487 -1.50247215376038 -2.26922737493233" />
    <parent
      link="right_ring_2" />
    <child
      link="ring_force_sensor_3" />
    <axis
      xyz="0 0 0" />
  </joint>
  <link
    name="ring_force_sensor_1">
    <inertial>
      <origin
        xyz="-5.90327958142033E-06 0.000116509445804644 -0.000567443259521572"
        rpy="0 0 0" />
      <mass
        value="0.001" />
      <inertia
        ixx="3.37799540185096E-09"
        ixy="7.60796091703617E-11"
        ixz="2.73854397843076E-13"
        iyy="1.96641957767428E-09"
        iyz="-5.47947431188363E-12"
        izz="5.28079735826682E-09" />
    </inertial>
    <visual>
      <origin
        xyz="0 0 0"
        rpy="0 0 0" />
      <geometry>
        <mesh
          filename="../meshes/ring_force_sensor_1.STL" />
      </geometry>
      <material
        name="">
        <color
          rgba="0.411764705882353 0.411764705882353 0.411764705882353 1" />
      </material>
    </visual>
    <collision>
      <origin
        xyz="0 0 0"
        rpy="0 0 0" />
      <geometry>
        <mesh
          filename="../meshes/ring_force_sensor_1.STL" />
      </geometry>
    </collision>
  </link>
  <joint
    name="ring_force_sensor_1_joint"
    type="fixed">
    <origin
      xyz="-0.0120461582060112 0.019648547178991 -0.00665098451502209"
      rpy="1.57079632679491 -1.51723862304532 -1.78288465285967" />
    <parent
      link="right_ring_1" />
    <child
      link="ring_force_sensor_1" />
    <axis
      xyz="0 0 0" />
  </joint>
  <link
    name="right_little_1">
    <inertial>
      <origin
        xyz="0.03325 0.00124 0.15954"
        rpy="0 0 0" />
      <mass
        value="0.02456" />
      <inertia
        ixx="6.15542e-06"
        ixy="-2.33e-08"
        ixz="-5.1287e-07"
        iyy="6.1396099999999995e-06"
        iyz="-2.3261000000000002e-07"
        izz="1.41681e-06" />
    </inertial>
    <visual>
      <origin
        xyz="0 0 0"
        rpy="0 0 0" />
      <geometry>
        <mesh
          filename="../meshes/right_little_1.STL" />
      </geometry>
      <material
        name="">
        <color
          rgba="1 1 1 1" />
      </material>
    </visual>
    <collision>
      <origin
        xyz="0 0 0"
        rpy="0 0 0" />
      <geometry>
        <mesh
          filename="../meshes/right_little_1.STL" />
      </geometry>
    </collision>
  </link>
  <joint
    name="right_little_1_joint"
    type="revolute">
    <origin
      xyz="0.025916 0.00056467 0.15365"
      rpy="1.4661 0 -1.5708" />
    <parent
      link="base_link" />
    <child
      link="right_little_1" />
    <axis
      xyz="0 0 1" />
    <limit
      lower="0"
      upper="1.4381"
      effort="10"
      velocity="1" />
  </joint>
  <link
    name="right_little_2">
    <inertial>
      <origin
        xyz="0.03867 -0.02782 0.20235"
        rpy="0 0 0" />
      <mass
        value="0.009720000000000001" />
      <inertia
        ixx="1.6975399999999999e-06"
        ixy="1.73e-09"
        ixz="-1.8642e-07"
        iyy="1.7773499999999998e-06"
        iyz="-2.2100000000000003e-08"
        izz="2.8921e-07" />
    </inertial>
    <visual>
      <origin
        xyz="0 0 0"
        rpy="0 0 0" />
      <geometry>
        <mesh
          filename="../meshes/right_little_2.STL" />
      </geometry>
      <material
        name="">
        <color
          rgba="1 1 1 1" />
      </material>
    </visual>
    <collision>
      <origin
        xyz="0 0 0"
        rpy="0 0 0" />
      <geometry>
        <mesh
          filename="../meshes/right_little_2.STL" />
      </geometry>
    </collision>
  </link>
  <joint
    name="right_little_2_joint"
    type="revolute">
    <origin
      xyz="-0.0034259 0.032596 -0.00055"
      rpy="0 0 0" />
    <parent
      link="right_little_1" />
    <child
      link="right_little_2" />
    <axis
      xyz="0 0 1" />
    <limit
      lower="0"
      upper="3.14"
      effort="10"
      velocity="1" />
    <mimic
        joint="right_little_1_joint"
        multiplier="1.0843"
        offset="0" />  
  </joint>
  <link
    name="little_force_sensor_2">
    <inertial>
      <origin
        xyz="1.83850807690782E-05 -0.000118792499944516 -0.00077353663965421"
        rpy="0 0 0" />
      <mass
        value="0.001" />
      <inertia
        ixx="5.36105565367509E-09"
        ixy="2.9087102385881E-10"
        ixz="-4.23704440233772E-12"
        iyy="2.78924633862048E-09"
        iyz="3.60734545957644E-11"
        izz="8.01055296833179E-09" />
    </inertial>
    <visual>
      <origin
        xyz="0 0 0"
        rpy="0 0 0" />
      <geometry>
        <mesh
          filename="../meshes/little_force_sensor_2.STL" />
      </geometry>
      <material
        name="">
        <color
          rgba="0.411764705882353 0.411764705882353 0.411764705882353 1" />
      </material>
    </visual>
    <collision>
      <origin
        xyz="0 0 0"
        rpy="0 0 0" />
      <geometry>
        <mesh
          filename="../meshes/little_force_sensor_2.STL" />
      </geometry>
    </collision>
  </link>
  <joint
    name="little_force_sensor_2_joint"
    type="fixed">
    <origin
      xyz="-0.00645123763174135 0.0276833479200767 -0.00611719352979621"
      rpy="1.57079632679488 -1.45969392221055 -1.22888814145719" />
    <parent
      link="right_little_2" />
    <child
      link="little_force_sensor_2" />
    <axis
      xyz="0 0 0" />
  </joint>
  <link
    name="little_force_sensor_3">
    <inertial>
      <origin
        xyz="6.36863053951123E-05 -0.000437236774208316 -0.00112814037373121"
        rpy="0 0 0" />
      <mass
        value="0.001" />
      <inertia
        ixx="1.11592356002466E-10"
        ixy="-1.48925479775264E-11"
        ixz="-1.18387481927136E-12"
        iyy="2.17209112811676E-10"
        iyz="8.07880135891967E-12"
        izz="2.52055535156648E-10" />
    </inertial>
    <visual>
      <origin
        xyz="0 0 0"
        rpy="0 0 0" />
      <geometry>
        <mesh
          filename="../meshes/little_force_sensor_3.STL" />
      </geometry>
      <material
        name="">
        <color
          rgba="0.411764705882353 0.411764705882353 0.411764705882353 1" />
      </material>
    </visual>
    <collision>
      <origin
        xyz="0 0 0"
        rpy="0 0 0" />
      <geometry>
        <mesh
          filename="../meshes/little_force_sensor_3.STL" />
      </geometry>
    </collision>
  </link>
  <joint
    name="little_force_sensor_3_joint"
    type="fixed">
    <origin
      xyz="-0.00639723214432697 0.042706921918282 -0.00611537168168175"
      rpy="1.5707963267949 -1.43362674619531 -2.2760856926538" />
    <parent
      link="right_little_2" />
    <child
      link="little_force_sensor_3" />
    <axis
      xyz="0 0 0" />
  </joint>
  <link
    name="little_force_sensor_1">
    <inertial>
      <origin
        xyz="-1.2130080955873E-05 0.000116026903212899 -0.00056744299424992"
        rpy="0 0 0" />
      <mass
        value="0.001" />
      <inertia
        ixx="3.3658199564233E-09"
        ixy="1.51080971417152E-10"
        ixz="5.66657100478518E-13"
        iyy="1.97859528185445E-09"
        iyz="-5.45672948532754E-12"
        izz="5.28079755559196E-09" />
    </inertial>
    <visual>
      <origin
        xyz="0 0 0"
        rpy="0 0 0" />
      <geometry>
        <mesh
          filename="../meshes/little_force_sensor_1.STL" />
      </geometry>
      <material
        name="">
        <color
          rgba="0.411764705882353 0.411764705882353 0.411764705882353 1" />
      </material>
    </visual>
    <collision>
      <origin
        xyz="0 0 0"
        rpy="0 0 0" />
      <geometry>
        <mesh
          filename="../meshes/little_force_sensor_1.STL" />
      </geometry>
    </collision>
  </link>
  <joint
    name="little_force_sensor_1_joint"
    type="fixed">
    <origin
      xyz="-0.0120461582060113 0.0196485471789908 -0.00665098451502223"
      rpy="1.5707963267949 -1.4636944932668 -1.78288465285966" />
    <parent
      link="right_little_1" />
    <child
      link="little_force_sensor_1" />
    <axis
      xyz="0 0 0" />
  </joint>

</robot>
